2024-09-21 16:14:54,577 INFO    MainThread:1092492 [wandb_setup.py:_flush():77] Current SDK version is 0.18.1
2024-09-21 16:14:54,577 INFO    MainThread:1092492 [wandb_setup.py:_flush():77] Configure stats pid to 1092492
2024-09-21 16:14:54,577 INFO    MainThread:1092492 [wandb_setup.py:_flush():77] Loading settings from /home/yutian/.config/wandb/settings
2024-09-21 16:14:54,577 INFO    MainThread:1092492 [wandb_setup.py:_flush():77] Loading settings from /home/yutian/quiet-star/wandb/settings
2024-09-21 16:14:54,577 INFO    MainThread:1092492 [wandb_setup.py:_flush():77] Loading settings from environment variables: {}
2024-09-21 16:14:54,577 INFO    MainThread:1092492 [wandb_setup.py:_flush():77] Applying setup settings: {'mode': None, '_disable_service': None}
2024-09-21 16:14:54,577 INFO    MainThread:1092492 [wandb_setup.py:_flush():77] Inferring run settings from compute environment: {'program_relpath': 'quiet-star-train.py', 'program_abspath': '/home/yutian/quiet-star/quiet-star-train.py', 'program': '/home/yutian/quiet-star/quiet-star-train.py'}
2024-09-21 16:14:54,577 INFO    MainThread:1092492 [wandb_setup.py:_flush():77] Applying login settings: {}
2024-09-21 16:14:54,577 INFO    MainThread:1092492 [wandb_init.py:_log_setup():532] Logging user logs to /home/yutian/quiet-star/wandb/run-20240921_161454-pntymdsa/logs/debug.log
2024-09-21 16:14:54,577 INFO    MainThread:1092492 [wandb_init.py:_log_setup():533] Logging internal logs to /home/yutian/quiet-star/wandb/run-20240921_161454-pntymdsa/logs/debug-internal.log
2024-09-21 16:14:54,577 INFO    MainThread:1092492 [wandb_init.py:init():616] calling init triggers
2024-09-21 16:14:54,577 INFO    MainThread:1092492 [wandb_init.py:init():623] wandb.init called with sweep_config: {}
config: {}
2024-09-21 16:14:54,577 INFO    MainThread:1092492 [wandb_init.py:init():666] starting backend
2024-09-21 16:14:54,577 INFO    MainThread:1092492 [wandb_init.py:init():670] setting up manager
2024-09-21 16:14:54,579 INFO    MainThread:1092492 [backend.py:_multiprocessing_setup():105] multiprocessing start_methods=fork,spawn,forkserver, using: spawn
2024-09-21 16:14:54,580 INFO    MainThread:1092492 [wandb_init.py:init():678] backend started and connected
2024-09-21 16:14:54,582 INFO    MainThread:1092492 [wandb_init.py:init():773] updated telemetry
2024-09-21 16:14:54,588 INFO    MainThread:1092492 [wandb_init.py:init():806] communicating run to backend with 90.0 second timeout
2024-09-21 16:15:52,852 INFO    Thread-4 (wrapped_target):1092492 [retry.py:__call__():172] Retry attempt failed:
Traceback (most recent call last):
  File "/home/yutian/miniconda3/lib/python3.12/site-packages/urllib3/connectionpool.py", line 467, in _make_request
    self._validate_conn(conn)
  File "/home/yutian/miniconda3/lib/python3.12/site-packages/urllib3/connectionpool.py", line 1096, in _validate_conn
    conn.connect()
  File "/home/yutian/miniconda3/lib/python3.12/site-packages/urllib3/connection.py", line 642, in connect
    sock_and_verified = _ssl_wrap_socket_and_match_hostname(
                        ^^^^^^^^^^^^^^^^^^^^^^^^^^^^^^^^^^^^
  File "/home/yutian/miniconda3/lib/python3.12/site-packages/urllib3/connection.py", line 782, in _ssl_wrap_socket_and_match_hostname
    ssl_sock = ssl_wrap_socket(
               ^^^^^^^^^^^^^^^^
  File "/home/yutian/miniconda3/lib/python3.12/site-packages/urllib3/util/ssl_.py", line 470, in ssl_wrap_socket
    ssl_sock = _ssl_wrap_socket_impl(sock, context, tls_in_tls, server_hostname)
               ^^^^^^^^^^^^^^^^^^^^^^^^^^^^^^^^^^^^^^^^^^^^^^^^^^^^^^^^^^^^^^^^^
  File "/home/yutian/miniconda3/lib/python3.12/site-packages/urllib3/util/ssl_.py", line 514, in _ssl_wrap_socket_impl
    return ssl_context.wrap_socket(sock, server_hostname=server_hostname)
           ^^^^^^^^^^^^^^^^^^^^^^^^^^^^^^^^^^^^^^^^^^^^^^^^^^^^^^^^^^^^^^
  File "/home/yutian/miniconda3/lib/python3.12/ssl.py", line 455, in wrap_socket
    return self.sslsocket_class._create(
           ^^^^^^^^^^^^^^^^^^^^^^^^^^^^^
  File "/home/yutian/miniconda3/lib/python3.12/ssl.py", line 1046, in _create
    self.do_handshake()
  File "/home/yutian/miniconda3/lib/python3.12/ssl.py", line 1321, in do_handshake
    self._sslobj.do_handshake()
TimeoutError: _ssl.c:983: The handshake operation timed out

The above exception was the direct cause of the following exception:

Traceback (most recent call last):
  File "/home/yutian/miniconda3/lib/python3.12/site-packages/requests/adapters.py", line 667, in send
    resp = conn.urlopen(
           ^^^^^^^^^^^^^
  File "/home/yutian/miniconda3/lib/python3.12/site-packages/urllib3/connectionpool.py", line 844, in urlopen
    retries = retries.increment(
              ^^^^^^^^^^^^^^^^^^
  File "/home/yutian/miniconda3/lib/python3.12/site-packages/urllib3/util/retry.py", line 470, in increment
    raise reraise(type(error), error, _stacktrace)
          ^^^^^^^^^^^^^^^^^^^^^^^^^^^^^^^^^^^^^^^^
  File "/home/yutian/miniconda3/lib/python3.12/site-packages/urllib3/util/util.py", line 39, in reraise
    raise value
  File "/home/yutian/miniconda3/lib/python3.12/site-packages/urllib3/connectionpool.py", line 790, in urlopen
    response = self._make_request(
               ^^^^^^^^^^^^^^^^^^^
  File "/home/yutian/miniconda3/lib/python3.12/site-packages/urllib3/connectionpool.py", line 491, in _make_request
    raise new_e
  File "/home/yutian/miniconda3/lib/python3.12/site-packages/urllib3/connectionpool.py", line 469, in _make_request
    self._raise_timeout(err=e, url=url, timeout_value=conn.timeout)
  File "/home/yutian/miniconda3/lib/python3.12/site-packages/urllib3/connectionpool.py", line 370, in _raise_timeout
    raise ReadTimeoutError(
urllib3.exceptions.ReadTimeoutError: HTTPSConnectionPool(host='api.wandb.ai', port=443): Read timed out. (read timeout=20)

During handling of the above exception, another exception occurred:

Traceback (most recent call last):
  File "/home/yutian/miniconda3/lib/python3.12/site-packages/wandb/sdk/lib/retry.py", line 131, in __call__
    result = self._call_fn(*args, **kwargs)
             ^^^^^^^^^^^^^^^^^^^^^^^^^^^^^^
  File "/home/yutian/miniconda3/lib/python3.12/site-packages/wandb/sdk/internal/internal_api.py", line 345, in execute
    return self.client.execute(*args, **kwargs)  # type: ignore
           ^^^^^^^^^^^^^^^^^^^^^^^^^^^^^^^^^^^^
  File "/home/yutian/miniconda3/lib/python3.12/site-packages/wandb/vendor/gql-0.2.0/wandb_gql/client.py", line 52, in execute
    result = self._get_result(document, *args, **kwargs)
             ^^^^^^^^^^^^^^^^^^^^^^^^^^^^^^^^^^^^^^^^^^^
  File "/home/yutian/miniconda3/lib/python3.12/site-packages/wandb/vendor/gql-0.2.0/wandb_gql/client.py", line 60, in _get_result
    return self.transport.execute(document, *args, **kwargs)
           ^^^^^^^^^^^^^^^^^^^^^^^^^^^^^^^^^^^^^^^^^^^^^^^^^
  File "/home/yutian/miniconda3/lib/python3.12/site-packages/wandb/sdk/lib/gql_request.py", line 58, in execute
    request = self.session.post(self.url, **post_args)
              ^^^^^^^^^^^^^^^^^^^^^^^^^^^^^^^^^^^^^^^^
  File "/home/yutian/miniconda3/lib/python3.12/site-packages/requests/sessions.py", line 637, in post
    return self.request("POST", url, data=data, json=json, **kwargs)
           ^^^^^^^^^^^^^^^^^^^^^^^^^^^^^^^^^^^^^^^^^^^^^^^^^^^^^^^^^
  File "/home/yutian/miniconda3/lib/python3.12/site-packages/requests/sessions.py", line 589, in request
    resp = self.send(prep, **send_kwargs)
           ^^^^^^^^^^^^^^^^^^^^^^^^^^^^^^
  File "/home/yutian/miniconda3/lib/python3.12/site-packages/requests/sessions.py", line 703, in send
    r = adapter.send(request, **kwargs)
        ^^^^^^^^^^^^^^^^^^^^^^^^^^^^^^^
  File "/home/yutian/miniconda3/lib/python3.12/site-packages/requests/adapters.py", line 713, in send
    raise ReadTimeout(e, request=request)
requests.exceptions.ReadTimeout: HTTPSConnectionPool(host='api.wandb.ai', port=443): Read timed out. (read timeout=20)
2024-09-21 16:16:24,608 ERROR   MainThread:1092492 [wandb_init.py:init():832] encountered error: Run initialization has timed out after 90.0 sec. 
Please refer to the documentation for additional information: https://docs.wandb.ai/guides/track/tracking-faq#initstarterror-error-communicating-with-wandb-process-
2024-09-21 16:16:24,609 ERROR   MainThread:1092492 [wandb_init.py:init():1251] error in wandb.init()
Traceback (most recent call last):
  File "/home/yutian/miniconda3/lib/python3.12/site-packages/wandb/sdk/wandb_init.py", line 1241, in init
    return wi.init()
           ^^^^^^^^^
  File "/home/yutian/miniconda3/lib/python3.12/site-packages/wandb/sdk/wandb_init.py", line 838, in init
    raise error
wandb.errors.CommError: Run initialization has timed out after 90.0 sec. 
Please refer to the documentation for additional information: https://docs.wandb.ai/guides/track/tracking-faq#initstarterror-error-communicating-with-wandb-process-
2024-09-21 16:16:24,765 WARNING MsgRouterThr:1092492 [router.py:message_loop():77] message_loop has been closed
